[2025-06-30T07:01:59.364+0000] {taskinstance.py:1979} INFO - Dependencies all met for dep_context=non-requeueable deps ti=<TaskInstance: django_etl_monitor.run_etl_from_django manual__2025-06-30T07:01:57.416252+00:00 [queued]>
[2025-06-30T07:01:59.372+0000] {taskinstance.py:1979} INFO - Dependencies all met for dep_context=requeueable deps ti=<TaskInstance: django_etl_monitor.run_etl_from_django manual__2025-06-30T07:01:57.416252+00:00 [queued]>
[2025-06-30T07:01:59.374+0000] {taskinstance.py:2193} INFO - Starting attempt 1 of 1
[2025-06-30T07:01:59.387+0000] {taskinstance.py:2214} INFO - Executing <Task(PythonOperator): run_etl_from_django> on 2025-06-30 07:01:57.416252+00:00
[2025-06-30T07:01:59.393+0000] {standard_task_runner.py:60} INFO - Started process 60 to run task
[2025-06-30T07:01:59.397+0000] {standard_task_runner.py:87} INFO - Running: ['***', 'tasks', 'run', 'django_etl_monitor', 'run_etl_from_django', 'manual__2025-06-30T07:01:57.416252+00:00', '--job-id', '188', '--raw', '--subdir', 'DAGS_FOLDER/django_etl_monitor.py', '--cfg-path', '/tmp/tmppsq3ubpd']
[2025-06-30T07:01:59.400+0000] {standard_task_runner.py:88} INFO - Job 188: Subtask run_etl_from_django
[2025-06-30T07:01:59.456+0000] {task_command.py:423} INFO - Running <TaskInstance: django_etl_monitor.run_etl_from_django manual__2025-06-30T07:01:57.416252+00:00 [running]> on host 5e56d6b4b856
[2025-06-30T07:01:59.545+0000] {taskinstance.py:2510} INFO - Exporting env vars: AIRFLOW_CTX_DAG_OWNER='***' AIRFLOW_CTX_DAG_ID='django_etl_monitor' AIRFLOW_CTX_TASK_ID='run_etl_from_django' AIRFLOW_CTX_EXECUTION_DATE='2025-06-30T07:01:57.416252+00:00' AIRFLOW_CTX_TRY_NUMBER='1' AIRFLOW_CTX_DAG_RUN_ID='manual__2025-06-30T07:01:57.416252+00:00'
[2025-06-30T07:01:59.547+0000] {logging_mixin.py:188} INFO - [Airflow DAG] Received conf: {'job_id': 110, 'name': 'Filter Load', 'source_table': 'source_data', 'target_table': 'xyz1', 'transformation_rule': '{"nodes": [{"id": "1", "type": "custom", "data": {"label": "source_data", "type": "input"}, "position": {"x": -0.427775029658477, "y": 106.42777502965848}, "width": 201, "height": 42, "selected": true, "positionAbsolute": {"x": -0.427775029658477, "y": 106.42777502965848}, "dragging": false}, {"id": "2", "type": "custom", "data": {"label": "xyz1", "type": "output"}, "position": {"x": 500, "y": 100}, "width": 201, "height": 42, "selected": false, "dragging": false}, {"id": "3", "type": "custom", "data": {"label": "Filter", "type": "filter", "condition": "age>=40"}, "position": {"x": 251.6999505338527, "y": 94.03852888526146}, "width": 201, "height": 70, "selected": false, "positionAbsolute": {"x": 251.6999505338527, "y": 94.03852888526146}, "dragging": false}], "edges": [{"source": "1", "sourceHandle": null, "target": "3", "targetHandle": null, "id": "1-3"}, {"source": "3", "sourceHandle": null, "target": "2", "targetHandle": null, "id": "3-2"}]}'}
[2025-06-30T07:01:59.627+0000] {logging_mixin.py:188} INFO - Pipeline parse error or not a pipeline: connection to server at "localhost" (::1), port 5432 failed: Connection refused
	Is the server running on that host and accepting TCP/IP connections?
connection to server at "localhost" (127.0.0.1), port 5432 failed: Connection refused
	Is the server running on that host and accepting TCP/IP connections?
[2025-06-30T07:01:59.628+0000] {taskinstance.py:2728} ERROR - Task failed with exception
Traceback (most recent call last):
  File "/home/airflow/.local/lib/python3.8/site-packages/django/db/backends/base/base.py", line 288, in ensure_connection
    self.connect()
  File "/home/airflow/.local/lib/python3.8/site-packages/django/utils/asyncio.py", line 26, in inner
    return func(*args, **kwargs)
  File "/home/airflow/.local/lib/python3.8/site-packages/django/db/backends/base/base.py", line 269, in connect
    self.connection = self.get_new_connection(conn_params)
  File "/home/airflow/.local/lib/python3.8/site-packages/django/utils/asyncio.py", line 26, in inner
    return func(*args, **kwargs)
  File "/home/airflow/.local/lib/python3.8/site-packages/django/db/backends/postgresql/base.py", line 275, in get_new_connection
    connection = self.Database.connect(**conn_params)
  File "/home/airflow/.local/lib/python3.8/site-packages/psycopg2/__init__.py", line 122, in connect
    conn = _connect(dsn, connection_factory=connection_factory, **kwasync)
psycopg2.OperationalError: connection to server at "localhost" (::1), port 5432 failed: Connection refused
	Is the server running on that host and accepting TCP/IP connections?
connection to server at "localhost" (127.0.0.1), port 5432 failed: Connection refused
	Is the server running on that host and accepting TCP/IP connections?


The above exception was the direct cause of the following exception:

Traceback (most recent call last):
  File "/home/airflow/.local/lib/python3.8/site-packages/airflow/models/taskinstance.py", line 444, in _execute_task
    result = _execute_callable(context=context, **execute_callable_kwargs)
  File "/home/airflow/.local/lib/python3.8/site-packages/airflow/models/taskinstance.py", line 414, in _execute_callable
    return execute_callable(context=context, **execute_callable_kwargs)
  File "/home/airflow/.local/lib/python3.8/site-packages/airflow/operators/python.py", line 200, in execute
    return_value = self.execute_callable()
  File "/home/airflow/.local/lib/python3.8/site-packages/airflow/operators/python.py", line 217, in execute_callable
    return self.python_callable(*self.op_args, **self.op_kwargs)
  File "/opt/airflow/dags/django_etl_monitor.py", line 48, in run_etl_from_conf
    run_etl_job(job)
  File "/opt/airflow/etl_tool/etl_app/etl/etl_executor.py", line 179, in run_etl_job
    df_result = apply_pipeline(df, pipeline['nodes'], pipeline['edges'], job)
  File "/opt/airflow/etl_tool/etl_app/etl/etl_executor.py", line 161, in apply_pipeline
    log_node_status(job.id, node['id'], node['data']['type'], 'success')
  File "/opt/airflow/etl_tool/etl_app/etl/etl_executor.py", line 257, in log_node_status
    ETLNodeStatus.objects.create(
  File "/home/airflow/.local/lib/python3.8/site-packages/django/db/models/manager.py", line 87, in manager_method
    return getattr(self.get_queryset(), name)(*args, **kwargs)
  File "/home/airflow/.local/lib/python3.8/site-packages/django/db/models/query.py", line 658, in create
    obj.save(force_insert=True, using=self.db)
  File "/home/airflow/.local/lib/python3.8/site-packages/django/db/models/base.py", line 814, in save
    self.save_base(
  File "/home/airflow/.local/lib/python3.8/site-packages/django/db/models/base.py", line 877, in save_base
    updated = self._save_table(
  File "/home/airflow/.local/lib/python3.8/site-packages/django/db/models/base.py", line 1020, in _save_table
    results = self._do_insert(
  File "/home/airflow/.local/lib/python3.8/site-packages/django/db/models/base.py", line 1061, in _do_insert
    return manager._insert(
  File "/home/airflow/.local/lib/python3.8/site-packages/django/db/models/manager.py", line 87, in manager_method
    return getattr(self.get_queryset(), name)(*args, **kwargs)
  File "/home/airflow/.local/lib/python3.8/site-packages/django/db/models/query.py", line 1805, in _insert
    return query.get_compiler(using=using).execute_sql(returning_fields)
  File "/home/airflow/.local/lib/python3.8/site-packages/django/db/models/sql/compiler.py", line 1820, in execute_sql
    with self.connection.cursor() as cursor:
  File "/home/airflow/.local/lib/python3.8/site-packages/django/utils/asyncio.py", line 26, in inner
    return func(*args, **kwargs)
  File "/home/airflow/.local/lib/python3.8/site-packages/django/db/backends/base/base.py", line 329, in cursor
    return self._cursor()
  File "/home/airflow/.local/lib/python3.8/site-packages/django/db/backends/base/base.py", line 305, in _cursor
    self.ensure_connection()
  File "/home/airflow/.local/lib/python3.8/site-packages/django/utils/asyncio.py", line 26, in inner
    return func(*args, **kwargs)
  File "/home/airflow/.local/lib/python3.8/site-packages/django/db/backends/base/base.py", line 288, in ensure_connection
    self.connect()
  File "/home/airflow/.local/lib/python3.8/site-packages/django/db/utils.py", line 91, in __exit__
    raise dj_exc_value.with_traceback(traceback) from exc_value
  File "/home/airflow/.local/lib/python3.8/site-packages/django/db/backends/base/base.py", line 288, in ensure_connection
    self.connect()
  File "/home/airflow/.local/lib/python3.8/site-packages/django/utils/asyncio.py", line 26, in inner
    return func(*args, **kwargs)
  File "/home/airflow/.local/lib/python3.8/site-packages/django/db/backends/base/base.py", line 269, in connect
    self.connection = self.get_new_connection(conn_params)
  File "/home/airflow/.local/lib/python3.8/site-packages/django/utils/asyncio.py", line 26, in inner
    return func(*args, **kwargs)
  File "/home/airflow/.local/lib/python3.8/site-packages/django/db/backends/postgresql/base.py", line 275, in get_new_connection
    connection = self.Database.connect(**conn_params)
  File "/home/airflow/.local/lib/python3.8/site-packages/psycopg2/__init__.py", line 122, in connect
    conn = _connect(dsn, connection_factory=connection_factory, **kwasync)
django.db.utils.OperationalError: connection to server at "localhost" (::1), port 5432 failed: Connection refused
	Is the server running on that host and accepting TCP/IP connections?
connection to server at "localhost" (127.0.0.1), port 5432 failed: Connection refused
	Is the server running on that host and accepting TCP/IP connections?

[2025-06-30T07:01:59.667+0000] {taskinstance.py:1149} INFO - Marking task as FAILED. dag_id=django_etl_monitor, task_id=run_etl_from_django, execution_date=20250630T070157, start_date=20250630T070159, end_date=20250630T070159
[2025-06-30T07:01:59.684+0000] {standard_task_runner.py:107} ERROR - Failed to execute job 188 for task run_etl_from_django (connection to server at "localhost" (::1), port 5432 failed: Connection refused
	Is the server running on that host and accepting TCP/IP connections?
connection to server at "localhost" (127.0.0.1), port 5432 failed: Connection refused
	Is the server running on that host and accepting TCP/IP connections?
; 60)
[2025-06-30T07:01:59.731+0000] {local_task_job_runner.py:234} INFO - Task exited with return code 1
[2025-06-30T07:01:59.747+0000] {taskinstance.py:3309} INFO - 0 downstream tasks scheduled from follow-on schedule check
