[2025-06-25T07:05:47.368+0000] {taskinstance.py:1979} INFO - Dependencies all met for dep_context=non-requeueable deps ti=<TaskInstance: django_etl_monitor.run_etl_from_django manual__2025-06-25T07:05:45.975601+00:00 [queued]>
[2025-06-25T07:05:47.375+0000] {taskinstance.py:1979} INFO - Dependencies all met for dep_context=requeueable deps ti=<TaskInstance: django_etl_monitor.run_etl_from_django manual__2025-06-25T07:05:45.975601+00:00 [queued]>
[2025-06-25T07:05:47.376+0000] {taskinstance.py:2193} INFO - Starting attempt 1 of 1
[2025-06-25T07:05:47.389+0000] {taskinstance.py:2214} INFO - Executing <Task(PythonOperator): run_etl_from_django> on 2025-06-25 07:05:45.975601+00:00
[2025-06-25T07:05:47.393+0000] {standard_task_runner.py:60} INFO - Started process 71 to run task
[2025-06-25T07:05:47.397+0000] {standard_task_runner.py:87} INFO - Running: ['***', 'tasks', 'run', 'django_etl_monitor', 'run_etl_from_django', 'manual__2025-06-25T07:05:45.975601+00:00', '--job-id', '101', '--raw', '--subdir', 'DAGS_FOLDER/django_etl_monitor.py', '--cfg-path', '/tmp/tmpr07ud2es']
[2025-06-25T07:05:47.399+0000] {standard_task_runner.py:88} INFO - Job 101: Subtask run_etl_from_django
[2025-06-25T07:05:47.443+0000] {task_command.py:423} INFO - Running <TaskInstance: django_etl_monitor.run_etl_from_django manual__2025-06-25T07:05:45.975601+00:00 [running]> on host 2df34b4adfe5
[2025-06-25T07:05:47.509+0000] {taskinstance.py:2510} INFO - Exporting env vars: AIRFLOW_CTX_DAG_OWNER='***' AIRFLOW_CTX_DAG_ID='django_etl_monitor' AIRFLOW_CTX_TASK_ID='run_etl_from_django' AIRFLOW_CTX_EXECUTION_DATE='2025-06-25T07:05:45.975601+00:00' AIRFLOW_CTX_TRY_NUMBER='1' AIRFLOW_CTX_DAG_RUN_ID='manual__2025-06-25T07:05:45.975601+00:00'
[2025-06-25T07:05:47.510+0000] {logging_mixin.py:188} INFO - [Airflow DAG] Received conf: {'job_id': 66, 'name': 'One-to-One Load', 'source_table': 'source_date', 'target_table': 'xyz', 'transformation_rule': ''}
[2025-06-25T07:05:47.511+0000] {logging_mixin.py:188} INFO - Pipeline parse error or not a pipeline: Expecting value: line 1 column 1 (char 0)
[2025-06-25T07:05:47.572+0000] {taskinstance.py:2728} ERROR - Task failed with exception
Traceback (most recent call last):
  File "/home/airflow/.local/lib/python3.8/site-packages/airflow/models/taskinstance.py", line 444, in _execute_task
    result = _execute_callable(context=context, **execute_callable_kwargs)
  File "/home/airflow/.local/lib/python3.8/site-packages/airflow/models/taskinstance.py", line 414, in _execute_callable
    return execute_callable(context=context, **execute_callable_kwargs)
  File "/home/airflow/.local/lib/python3.8/site-packages/airflow/operators/python.py", line 200, in execute
    return_value = self.execute_callable()
  File "/home/airflow/.local/lib/python3.8/site-packages/airflow/operators/python.py", line 217, in execute_callable
    return self.python_callable(*self.op_args, **self.op_kwargs)
  File "/opt/airflow/dags/django_etl_monitor.py", line 41, in run_etl_from_conf
    run_etl_job(job)
  File "/opt/airflow/etl_tool/etl_app/etl/etl_executor.py", line 139, in run_etl_job
    cur.execute(create_sql)
psycopg2.errors.UndefinedTable: relation "source_date" does not exist
LINE 1: CREATE TABLE xyz AS SELECT  FROM source_date;
                                         ^

[2025-06-25T07:05:47.609+0000] {taskinstance.py:1149} INFO - Marking task as FAILED. dag_id=django_etl_monitor, task_id=run_etl_from_django, execution_date=20250625T070545, start_date=20250625T070547, end_date=20250625T070547
[2025-06-25T07:05:47.623+0000] {standard_task_runner.py:107} ERROR - Failed to execute job 101 for task run_etl_from_django (relation "source_date" does not exist
LINE 1: CREATE TABLE xyz AS SELECT  FROM source_date;
                                         ^
; 71)
[2025-06-25T07:05:47.650+0000] {local_task_job_runner.py:234} INFO - Task exited with return code 1
[2025-06-25T07:05:47.677+0000] {taskinstance.py:3309} INFO - 0 downstream tasks scheduled from follow-on schedule check
