[2025-06-24T10:18:01.945+0000] {taskinstance.py:1979} INFO - Dependencies all met for dep_context=non-requeueable deps ti=<TaskInstance: django_etl_monitor.run_etl_from_django manual__2025-06-24T10:18:01.064870+00:00 [queued]>
[2025-06-24T10:18:01.962+0000] {taskinstance.py:1979} INFO - Dependencies all met for dep_context=requeueable deps ti=<TaskInstance: django_etl_monitor.run_etl_from_django manual__2025-06-24T10:18:01.064870+00:00 [queued]>
[2025-06-24T10:18:01.963+0000] {taskinstance.py:2193} INFO - Starting attempt 1 of 1
[2025-06-24T10:18:01.985+0000] {taskinstance.py:2214} INFO - Executing <Task(PythonOperator): run_etl_from_django> on 2025-06-24 10:18:01.064870+00:00
[2025-06-24T10:18:01.992+0000] {standard_task_runner.py:60} INFO - Started process 76 to run task
[2025-06-24T10:18:01.997+0000] {standard_task_runner.py:87} INFO - Running: ['***', 'tasks', 'run', 'django_etl_monitor', 'run_etl_from_django', 'manual__2025-06-24T10:18:01.064870+00:00', '--job-id', '87', '--raw', '--subdir', 'DAGS_FOLDER/django_etl_monitor.py', '--cfg-path', '/tmp/tmpg7et7aih']
[2025-06-24T10:18:02.000+0000] {standard_task_runner.py:88} INFO - Job 87: Subtask run_etl_from_django
[2025-06-24T10:18:02.101+0000] {task_command.py:423} INFO - Running <TaskInstance: django_etl_monitor.run_etl_from_django manual__2025-06-24T10:18:01.064870+00:00 [running]> on host 78d664e26a7a
[2025-06-24T10:18:02.306+0000] {taskinstance.py:2510} INFO - Exporting env vars: AIRFLOW_CTX_DAG_OWNER='***' AIRFLOW_CTX_DAG_ID='django_etl_monitor' AIRFLOW_CTX_TASK_ID='run_etl_from_django' AIRFLOW_CTX_EXECUTION_DATE='2025-06-24T10:18:01.064870+00:00' AIRFLOW_CTX_TRY_NUMBER='1' AIRFLOW_CTX_DAG_RUN_ID='manual__2025-06-24T10:18:01.064870+00:00'
[2025-06-24T10:18:02.551+0000] {taskinstance.py:2728} ERROR - Task failed with exception
Traceback (most recent call last):
  File "/home/airflow/.local/lib/python3.8/site-packages/airflow/models/taskinstance.py", line 444, in _execute_task
    result = _execute_callable(context=context, **execute_callable_kwargs)
  File "/home/airflow/.local/lib/python3.8/site-packages/airflow/models/taskinstance.py", line 414, in _execute_callable
    return execute_callable(context=context, **execute_callable_kwargs)
  File "/home/airflow/.local/lib/python3.8/site-packages/airflow/operators/python.py", line 200, in execute
    return_value = self.execute_callable()
  File "/home/airflow/.local/lib/python3.8/site-packages/airflow/operators/python.py", line 217, in execute_callable
    return self.python_callable(*self.op_args, **self.op_kwargs)
  File "/opt/airflow/dags/django_etl_monitor.py", line 77, in run_etl_from_conf
    cur.execute(f"INSERT INTO {target_table} ({', '.join(output_columns)}) VALUES ({placeholders})", row)
psycopg2.errors.UndefinedTable: relation "xyz" does not exist
LINE 1: INSERT INTO xyz (name_upper, age, bonus) VALUES ('ALICE', 'a...
                    ^

[2025-06-24T10:18:02.592+0000] {taskinstance.py:1149} INFO - Marking task as FAILED. dag_id=django_etl_monitor, task_id=run_etl_from_django, execution_date=20250624T101801, start_date=20250624T101801, end_date=20250624T101802
[2025-06-24T10:18:02.628+0000] {standard_task_runner.py:107} ERROR - Failed to execute job 87 for task run_etl_from_django (relation "xyz" does not exist
LINE 1: INSERT INTO xyz (name_upper, age, bonus) VALUES ('ALICE', 'a...
                    ^
; 76)
[2025-06-24T10:18:02.656+0000] {local_task_job_runner.py:234} INFO - Task exited with return code 1
[2025-06-24T10:18:02.693+0000] {taskinstance.py:3309} INFO - 0 downstream tasks scheduled from follow-on schedule check
