[2025-06-26T06:20:56.947+0000] {taskinstance.py:1979} INFO - Dependencies all met for dep_context=non-requeueable deps ti=<TaskInstance: django_etl_monitor.run_etl_from_django manual__2025-06-26T06:20:54.696603+00:00 [queued]>
[2025-06-26T06:20:56.964+0000] {taskinstance.py:1979} INFO - Dependencies all met for dep_context=requeueable deps ti=<TaskInstance: django_etl_monitor.run_etl_from_django manual__2025-06-26T06:20:54.696603+00:00 [queued]>
[2025-06-26T06:20:56.965+0000] {taskinstance.py:2193} INFO - Starting attempt 1 of 1
[2025-06-26T06:20:57.031+0000] {taskinstance.py:2214} INFO - Executing <Task(PythonOperator): run_etl_from_django> on 2025-06-26 06:20:54.696603+00:00
[2025-06-26T06:20:57.038+0000] {standard_task_runner.py:60} INFO - Started process 62 to run task
[2025-06-26T06:20:57.044+0000] {standard_task_runner.py:87} INFO - Running: ['***', 'tasks', 'run', 'django_etl_monitor', 'run_etl_from_django', 'manual__2025-06-26T06:20:54.696603+00:00', '--job-id', '143', '--raw', '--subdir', 'DAGS_FOLDER/django_etl_monitor.py', '--cfg-path', '/tmp/tmpvpsai7gk']
[2025-06-26T06:20:57.048+0000] {standard_task_runner.py:88} INFO - Job 143: Subtask run_etl_from_django
[2025-06-26T06:20:57.162+0000] {task_command.py:423} INFO - Running <TaskInstance: django_etl_monitor.run_etl_from_django manual__2025-06-26T06:20:54.696603+00:00 [running]> on host e384131eec2a
[2025-06-26T06:20:57.343+0000] {taskinstance.py:2510} INFO - Exporting env vars: AIRFLOW_CTX_DAG_OWNER='***' AIRFLOW_CTX_DAG_ID='django_etl_monitor' AIRFLOW_CTX_TASK_ID='run_etl_from_django' AIRFLOW_CTX_EXECUTION_DATE='2025-06-26T06:20:54.696603+00:00' AIRFLOW_CTX_TRY_NUMBER='1' AIRFLOW_CTX_DAG_RUN_ID='manual__2025-06-26T06:20:54.696603+00:00'
[2025-06-26T06:20:57.346+0000] {logging_mixin.py:188} INFO - [Airflow DAG] Received conf: {'job_id': 94, 'name': 'One-to-One Load', 'source_table': 'Source_data', 'target_table': 'xyz', 'transformation_rule': '{"nodes": [{"id": "1", "type": "custom", "data": {"label": "Source_data", "type": "input"}, "position": {"x": 0, "y": 100}, "width": 201, "height": 42, "selected": false, "dragging": false}, {"id": "2", "type": "custom", "data": {"label": "xyz", "type": "output"}, "position": {"x": 500, "y": 100}, "width": 201, "height": 42, "selected": true, "dragging": false}], "edges": [{"source": "1", "sourceHandle": null, "target": "2", "targetHandle": null, "id": "1-2"}]}'}
[2025-06-26T06:20:57.454+0000] {logging_mixin.py:188} INFO - Pipeline parse error or not a pipeline: (psycopg2.errors.UndefinedTable) relation "Source_data" does not exist
LINE 1: SELECT * FROM "Source_data"
                      ^

[SQL: SELECT * FROM "Source_data"]
(Background on this error at: https://sqlalche.me/e/14/f405)
[2025-06-26T06:20:57.455+0000] {taskinstance.py:2728} ERROR - Task failed with exception
Traceback (most recent call last):
  File "/home/airflow/.local/lib/python3.8/site-packages/sqlalchemy/engine/base.py", line 1910, in _execute_context
    self.dialect.do_execute(
  File "/home/airflow/.local/lib/python3.8/site-packages/sqlalchemy/engine/default.py", line 736, in do_execute
    cursor.execute(statement, parameters)
psycopg2.errors.UndefinedTable: relation "Source_data" does not exist
LINE 1: SELECT * FROM "Source_data"
                      ^


The above exception was the direct cause of the following exception:

Traceback (most recent call last):
  File "/home/airflow/.local/lib/python3.8/site-packages/airflow/models/taskinstance.py", line 444, in _execute_task
    result = _execute_callable(context=context, **execute_callable_kwargs)
  File "/home/airflow/.local/lib/python3.8/site-packages/airflow/models/taskinstance.py", line 414, in _execute_callable
    return execute_callable(context=context, **execute_callable_kwargs)
  File "/home/airflow/.local/lib/python3.8/site-packages/airflow/operators/python.py", line 200, in execute
    return_value = self.execute_callable()
  File "/home/airflow/.local/lib/python3.8/site-packages/airflow/operators/python.py", line 217, in execute_callable
    return self.python_callable(*self.op_args, **self.op_kwargs)
  File "/opt/airflow/dags/django_etl_monitor.py", line 41, in run_etl_from_conf
    run_etl_job(job)
  File "/opt/airflow/etl_tool/etl_app/etl/etl_executor.py", line 118, in run_etl_job
    df = pd.read_sql(f'SELECT * FROM "{source_table}"', engine)
  File "/home/airflow/.local/lib/python3.8/site-packages/pandas/io/sql.py", line 663, in read_sql
    return pandas_sql.read_query(
  File "/home/airflow/.local/lib/python3.8/site-packages/pandas/io/sql.py", line 1738, in read_query
    result = self.execute(sql, params)
  File "/home/airflow/.local/lib/python3.8/site-packages/pandas/io/sql.py", line 1562, in execute
    return self.con.exec_driver_sql(sql, *args)
  File "/home/airflow/.local/lib/python3.8/site-packages/sqlalchemy/engine/base.py", line 1770, in exec_driver_sql
    return self._exec_driver_sql(
  File "/home/airflow/.local/lib/python3.8/site-packages/sqlalchemy/engine/base.py", line 1674, in _exec_driver_sql
    ret = self._execute_context(
  File "/home/airflow/.local/lib/python3.8/site-packages/sqlalchemy/engine/base.py", line 1953, in _execute_context
    self._handle_dbapi_exception(
  File "/home/airflow/.local/lib/python3.8/site-packages/sqlalchemy/engine/base.py", line 2134, in _handle_dbapi_exception
    util.raise_(
  File "/home/airflow/.local/lib/python3.8/site-packages/sqlalchemy/util/compat.py", line 211, in raise_
    raise exception
  File "/home/airflow/.local/lib/python3.8/site-packages/sqlalchemy/engine/base.py", line 1910, in _execute_context
    self.dialect.do_execute(
  File "/home/airflow/.local/lib/python3.8/site-packages/sqlalchemy/engine/default.py", line 736, in do_execute
    cursor.execute(statement, parameters)
sqlalchemy.exc.ProgrammingError: (psycopg2.errors.UndefinedTable) relation "Source_data" does not exist
LINE 1: SELECT * FROM "Source_data"
                      ^

[SQL: SELECT * FROM "Source_data"]
(Background on this error at: https://sqlalche.me/e/14/f405)
[2025-06-26T06:20:57.521+0000] {taskinstance.py:1149} INFO - Marking task as FAILED. dag_id=django_etl_monitor, task_id=run_etl_from_django, execution_date=20250626T062054, start_date=20250626T062056, end_date=20250626T062057
[2025-06-26T06:20:57.547+0000] {standard_task_runner.py:107} ERROR - Failed to execute job 143 for task run_etl_from_django ((psycopg2.errors.UndefinedTable) relation "Source_data" does not exist
LINE 1: SELECT * FROM "Source_data"
                      ^

[SQL: SELECT * FROM "Source_data"]
(Background on this error at: https://sqlalche.me/e/14/f405); 62)
[2025-06-26T06:20:57.580+0000] {local_task_job_runner.py:234} INFO - Task exited with return code 1
[2025-06-26T06:20:57.612+0000] {taskinstance.py:3309} INFO - 0 downstream tasks scheduled from follow-on schedule check
