[2025-06-30T09:01:13.896+0000] {scheduler_job_runner.py:781} ERROR - Executor reports task instance <TaskInstance: django_etl_monitor.source_data_1 manual__2025-06-30T09:01:10.416302+00:00 [queued]> finished (failed) although the task says it's queued. (Info: None) Was the task killed externally?
