[2025-06-25T10:04:02.193+0000] {taskinstance.py:1979} INFO - Dependencies all met for dep_context=non-requeueable deps ti=<TaskInstance: django_etl_monitor.run_etl_from_django manual__2025-06-25T10:04:00.208609+00:00 [queued]>
[2025-06-25T10:04:02.205+0000] {taskinstance.py:1979} INFO - Dependencies all met for dep_context=requeueable deps ti=<TaskInstance: django_etl_monitor.run_etl_from_django manual__2025-06-25T10:04:00.208609+00:00 [queued]>
[2025-06-25T10:04:02.206+0000] {taskinstance.py:2193} INFO - Starting attempt 1 of 1
[2025-06-25T10:04:02.224+0000] {taskinstance.py:2214} INFO - Executing <Task(PythonOperator): run_etl_from_django> on 2025-06-25 10:04:00.208609+00:00
[2025-06-25T10:04:02.230+0000] {standard_task_runner.py:60} INFO - Started process 58 to run task
[2025-06-25T10:04:02.235+0000] {standard_task_runner.py:87} INFO - Running: ['***', 'tasks', 'run', 'django_etl_monitor', 'run_etl_from_django', 'manual__2025-06-25T10:04:00.208609+00:00', '--job-id', '113', '--raw', '--subdir', 'DAGS_FOLDER/django_etl_monitor.py', '--cfg-path', '/tmp/tmpe6aqbc_g']
[2025-06-25T10:04:02.245+0000] {standard_task_runner.py:88} INFO - Job 113: Subtask run_etl_from_django
[2025-06-25T10:04:02.300+0000] {task_command.py:423} INFO - Running <TaskInstance: django_etl_monitor.run_etl_from_django manual__2025-06-25T10:04:00.208609+00:00 [running]> on host 2df34b4adfe5
[2025-06-25T10:04:02.376+0000] {taskinstance.py:2510} INFO - Exporting env vars: AIRFLOW_CTX_DAG_OWNER='***' AIRFLOW_CTX_DAG_ID='django_etl_monitor' AIRFLOW_CTX_TASK_ID='run_etl_from_django' AIRFLOW_CTX_EXECUTION_DATE='2025-06-25T10:04:00.208609+00:00' AIRFLOW_CTX_TRY_NUMBER='1' AIRFLOW_CTX_DAG_RUN_ID='manual__2025-06-25T10:04:00.208609+00:00'
[2025-06-25T10:04:02.378+0000] {logging_mixin.py:188} INFO - [Airflow DAG] Received conf: {'job_id': 74, 'name': 'One-to-One Load', 'source_table': 'source_data', 'target_table': 'xyz', 'transformation_rule': ''}
[2025-06-25T10:04:02.380+0000] {logging_mixin.py:188} INFO - Pipeline parse error or not a pipeline: Expecting value: line 1 column 1 (char 0)
[2025-06-25T10:04:02.380+0000] {taskinstance.py:2728} ERROR - Task failed with exception
Traceback (most recent call last):
  File "/home/airflow/.local/lib/python3.8/site-packages/airflow/models/taskinstance.py", line 444, in _execute_task
    result = _execute_callable(context=context, **execute_callable_kwargs)
  File "/home/airflow/.local/lib/python3.8/site-packages/airflow/models/taskinstance.py", line 414, in _execute_callable
    return execute_callable(context=context, **execute_callable_kwargs)
  File "/home/airflow/.local/lib/python3.8/site-packages/airflow/operators/python.py", line 200, in execute
    return_value = self.execute_callable()
  File "/home/airflow/.local/lib/python3.8/site-packages/airflow/operators/python.py", line 217, in execute_callable
    return self.python_callable(*self.op_args, **self.op_kwargs)
  File "/opt/airflow/dags/django_etl_monitor.py", line 41, in run_etl_from_conf
    run_etl_job(job)
  File "/opt/airflow/etl_tool/etl_app/etl/etl_executor.py", line 91, in run_etl_job
    pipeline = json.loads(rule)
  File "/usr/local/lib/python3.8/json/__init__.py", line 357, in loads
    return _default_decoder.decode(s)
  File "/usr/local/lib/python3.8/json/decoder.py", line 337, in decode
    obj, end = self.raw_decode(s, idx=_w(s, 0).end())
  File "/usr/local/lib/python3.8/json/decoder.py", line 355, in raw_decode
    raise JSONDecodeError("Expecting value", s, err.value) from None
json.decoder.JSONDecodeError: Expecting value: line 1 column 1 (char 0)
[2025-06-25T10:04:02.428+0000] {taskinstance.py:1149} INFO - Marking task as FAILED. dag_id=django_etl_monitor, task_id=run_etl_from_django, execution_date=20250625T100400, start_date=20250625T100402, end_date=20250625T100402
[2025-06-25T10:04:02.448+0000] {standard_task_runner.py:107} ERROR - Failed to execute job 113 for task run_etl_from_django (Expecting value: line 1 column 1 (char 0); 58)
[2025-06-25T10:04:02.455+0000] {local_task_job_runner.py:234} INFO - Task exited with return code 1
[2025-06-25T10:04:02.478+0000] {taskinstance.py:3309} INFO - 0 downstream tasks scheduled from follow-on schedule check
