[2025-06-25T07:04:03.595+0000] {taskinstance.py:1979} INFO - Dependencies all met for dep_context=non-requeueable deps ti=<TaskInstance: django_etl_monitor.run_etl_from_django manual__2025-06-25T07:04:02.097763+00:00 [queued]>
[2025-06-25T07:04:03.605+0000] {taskinstance.py:1979} INFO - Dependencies all met for dep_context=requeueable deps ti=<TaskInstance: django_etl_monitor.run_etl_from_django manual__2025-06-25T07:04:02.097763+00:00 [queued]>
[2025-06-25T07:04:03.606+0000] {taskinstance.py:2193} INFO - Starting attempt 1 of 1
[2025-06-25T07:04:03.622+0000] {taskinstance.py:2214} INFO - Executing <Task(PythonOperator): run_etl_from_django> on 2025-06-25 07:04:02.097763+00:00
[2025-06-25T07:04:03.627+0000] {standard_task_runner.py:60} INFO - Started process 68 to run task
[2025-06-25T07:04:03.630+0000] {standard_task_runner.py:87} INFO - Running: ['***', 'tasks', 'run', 'django_etl_monitor', 'run_etl_from_django', 'manual__2025-06-25T07:04:02.097763+00:00', '--job-id', '100', '--raw', '--subdir', 'DAGS_FOLDER/django_etl_monitor.py', '--cfg-path', '/tmp/tmpu6rkfij5']
[2025-06-25T07:04:03.633+0000] {standard_task_runner.py:88} INFO - Job 100: Subtask run_etl_from_django
[2025-06-25T07:04:03.682+0000] {task_command.py:423} INFO - Running <TaskInstance: django_etl_monitor.run_etl_from_django manual__2025-06-25T07:04:02.097763+00:00 [running]> on host 2df34b4adfe5
[2025-06-25T07:04:03.757+0000] {taskinstance.py:2510} INFO - Exporting env vars: AIRFLOW_CTX_DAG_OWNER='***' AIRFLOW_CTX_DAG_ID='django_etl_monitor' AIRFLOW_CTX_TASK_ID='run_etl_from_django' AIRFLOW_CTX_EXECUTION_DATE='2025-06-25T07:04:02.097763+00:00' AIRFLOW_CTX_TRY_NUMBER='1' AIRFLOW_CTX_DAG_RUN_ID='manual__2025-06-25T07:04:02.097763+00:00'
[2025-06-25T07:04:03.759+0000] {logging_mixin.py:188} INFO - [Airflow DAG] Received conf: {'job_id': 65, 'name': 'One-to-One Load', 'source_table': 'source_date', 'target_table': 'xyz', 'transformation_rule': ''}
[2025-06-25T07:04:03.760+0000] {taskinstance.py:2728} ERROR - Task failed with exception
Traceback (most recent call last):
  File "/home/airflow/.local/lib/python3.8/site-packages/airflow/models/taskinstance.py", line 444, in _execute_task
    result = _execute_callable(context=context, **execute_callable_kwargs)
  File "/home/airflow/.local/lib/python3.8/site-packages/airflow/models/taskinstance.py", line 414, in _execute_callable
    return execute_callable(context=context, **execute_callable_kwargs)
  File "/home/airflow/.local/lib/python3.8/site-packages/airflow/operators/python.py", line 200, in execute
    return_value = self.execute_callable()
  File "/home/airflow/.local/lib/python3.8/site-packages/airflow/operators/python.py", line 217, in execute_callable
    return self.python_callable(*self.op_args, **self.op_kwargs)
  File "/opt/airflow/dags/django_etl_monitor.py", line 27, in run_etl_from_conf
    raise ValueError(f"Missing job configuration in conf: {', '.join(missing)}. Full conf: {conf}")
ValueError: Missing job configuration in conf: transformation_rule. Full conf: {'job_id': 65, 'name': 'One-to-One Load', 'source_table': 'source_date', 'target_table': 'xyz', 'transformation_rule': ''}
[2025-06-25T07:04:03.774+0000] {taskinstance.py:1149} INFO - Marking task as FAILED. dag_id=django_etl_monitor, task_id=run_etl_from_django, execution_date=20250625T070402, start_date=20250625T070403, end_date=20250625T070403
[2025-06-25T07:04:03.785+0000] {standard_task_runner.py:107} ERROR - Failed to execute job 100 for task run_etl_from_django (Missing job configuration in conf: transformation_rule. Full conf: {'job_id': 65, 'name': 'One-to-One Load', 'source_table': 'source_date', 'target_table': 'xyz', 'transformation_rule': ''}; 68)
[2025-06-25T07:04:03.804+0000] {local_task_job_runner.py:234} INFO - Task exited with return code 1
[2025-06-25T07:04:03.819+0000] {taskinstance.py:3309} INFO - 0 downstream tasks scheduled from follow-on schedule check
