[2025-06-19T09:08:56.127+0000] {taskinstance.py:1979} INFO - Dependencies all met for dep_context=non-requeueable deps ti=<TaskInstance: django_etl_monitor.run_etl_from_django manual__2025-06-19T09:08:55.091495+00:00 [queued]>
[2025-06-19T09:08:56.134+0000] {taskinstance.py:1979} INFO - Dependencies all met for dep_context=requeueable deps ti=<TaskInstance: django_etl_monitor.run_etl_from_django manual__2025-06-19T09:08:55.091495+00:00 [queued]>
[2025-06-19T09:08:56.136+0000] {taskinstance.py:2193} INFO - Starting attempt 1 of 1
[2025-06-19T09:08:56.159+0000] {taskinstance.py:2214} INFO - Executing <Task(PythonOperator): run_etl_from_django> on 2025-06-19 09:08:55.091495+00:00
[2025-06-19T09:08:56.164+0000] {standard_task_runner.py:60} INFO - Started process 56 to run task
[2025-06-19T09:08:56.166+0000] {standard_task_runner.py:87} INFO - Running: ['***', 'tasks', 'run', 'django_etl_monitor', 'run_etl_from_django', 'manual__2025-06-19T09:08:55.091495+00:00', '--job-id', '11', '--raw', '--subdir', 'DAGS_FOLDER/django_etl_monitor.py', '--cfg-path', '/tmp/tmpgc_h72qj']
[2025-06-19T09:08:56.168+0000] {standard_task_runner.py:88} INFO - Job 11: Subtask run_etl_from_django
[2025-06-19T09:08:56.217+0000] {task_command.py:423} INFO - Running <TaskInstance: django_etl_monitor.run_etl_from_django manual__2025-06-19T09:08:55.091495+00:00 [running]> on host 13508eb9f306
[2025-06-19T09:08:56.277+0000] {taskinstance.py:2510} INFO - Exporting env vars: AIRFLOW_CTX_DAG_OWNER='***' AIRFLOW_CTX_DAG_ID='django_etl_monitor' AIRFLOW_CTX_TASK_ID='run_etl_from_django' AIRFLOW_CTX_EXECUTION_DATE='2025-06-19T09:08:55.091495+00:00' AIRFLOW_CTX_TRY_NUMBER='1' AIRFLOW_CTX_DAG_RUN_ID='manual__2025-06-19T09:08:55.091495+00:00'
[2025-06-19T09:08:56.305+0000] {taskinstance.py:2728} ERROR - Task failed with exception
Traceback (most recent call last):
  File "/home/airflow/.local/lib/python3.8/site-packages/airflow/models/taskinstance.py", line 444, in _execute_task
    result = _execute_callable(context=context, **execute_callable_kwargs)
  File "/home/airflow/.local/lib/python3.8/site-packages/airflow/models/taskinstance.py", line 414, in _execute_callable
    return execute_callable(context=context, **execute_callable_kwargs)
  File "/home/airflow/.local/lib/python3.8/site-packages/airflow/operators/python.py", line 200, in execute
    return_value = self.execute_callable()
  File "/home/airflow/.local/lib/python3.8/site-packages/airflow/operators/python.py", line 217, in execute_callable
    return self.python_callable(*self.op_args, **self.op_kwargs)
  File "/opt/airflow/dags/django_etl_monitor.py", line 16, in run_etl_from_conf
    conn = psycopg2.connect(
  File "/home/airflow/.local/lib/python3.8/site-packages/psycopg2/__init__.py", line 122, in connect
    conn = _connect(dsn, connection_factory=connection_factory, **kwasync)
psycopg2.OperationalError: connection to server at "172.16.16.85", port 5432 failed: FATAL:  no pg_hba.conf entry for host "172.16.16.85", user "postgres", database "etl_db", no encryption

[2025-06-19T09:08:56.320+0000] {taskinstance.py:1149} INFO - Marking task as FAILED. dag_id=django_etl_monitor, task_id=run_etl_from_django, execution_date=20250619T090855, start_date=20250619T090856, end_date=20250619T090856
[2025-06-19T09:08:56.330+0000] {standard_task_runner.py:107} ERROR - Failed to execute job 11 for task run_etl_from_django (connection to server at "172.16.16.85", port 5432 failed: FATAL:  no pg_hba.conf entry for host "172.16.16.85", user "postgres", database "etl_db", no encryption
; 56)
[2025-06-19T09:08:56.339+0000] {local_task_job_runner.py:234} INFO - Task exited with return code 1
[2025-06-19T09:08:56.353+0000] {taskinstance.py:3309} INFO - 0 downstream tasks scheduled from follow-on schedule check
